Traceback (most recent call last):
  File "/Users/juliettechampaud/opt/anaconda3/lib/python3.8/site-packages/jupyter_cache/executors/utils.py", line 51, in single_nb_execution
    executenb(
  File "/Users/juliettechampaud/opt/anaconda3/lib/python3.8/site-packages/nbclient/client.py", line 1112, in execute
    return NotebookClient(nb=nb, resources=resources, km=km, **kwargs).execute()
  File "/Users/juliettechampaud/opt/anaconda3/lib/python3.8/site-packages/nbclient/util.py", line 74, in wrapped
    return just_run(coro(*args, **kwargs))
  File "/Users/juliettechampaud/opt/anaconda3/lib/python3.8/site-packages/nbclient/util.py", line 53, in just_run
    return loop.run_until_complete(coro)
  File "/Users/juliettechampaud/opt/anaconda3/lib/python3.8/asyncio/base_events.py", line 616, in run_until_complete
    return future.result()
  File "/Users/juliettechampaud/opt/anaconda3/lib/python3.8/site-packages/nbclient/client.py", line 553, in async_execute
    await self.async_execute_cell(
  File "/Users/juliettechampaud/opt/anaconda3/lib/python3.8/site-packages/nbclient/client.py", line 857, in async_execute_cell
    self._check_raise_for_error(cell, exec_reply)
  File "/Users/juliettechampaud/opt/anaconda3/lib/python3.8/site-packages/nbclient/client.py", line 760, in _check_raise_for_error
    raise CellExecutionError.from_cell_and_msg(cell, exec_reply_content)
nbclient.exceptions.CellExecutionError: An error occurred while executing the following cell:
------------------
h = 0.41
x=np.arange(0,10,h)
f = lambda x,y: -5*y
ye = my_eulr(f,x,2)
yi = my_eulri(f,x,2)

xsol = np.linspace(0,10,1001)
ysol = 2*np.exp(-5*xsol)

fig,ax = plt.subplots(2,1)
ax[0].plot(x,ye,'b',xsol,ysol,'r')
ax[0].set_title('Explicit Method')
ax[0].set_xlim(0,10)
ax[1].plot(x, yi, 'b', xsol, ysol, 'r')
ax[1].set_title('Implicit Method')
ax[1].set_xlim(0,10)
fig.tight_layout()
plt.show()
------------------

[0;31m---------------------------------------------------------------------------[0m
[0;31mNameError[0m                                 Traceback (most recent call last)
[0;32m<ipython-input-9-709ab7c372e1>[0m in [0;36m<module>[0;34m[0m
[1;32m      3[0m [0mf[0m [0;34m=[0m [0;32mlambda[0m [0mx[0m[0;34m,[0m[0my[0m[0;34m:[0m [0;34m-[0m[0;36m5[0m[0;34m*[0m[0my[0m[0;34m[0m[0;34m[0m[0m
[1;32m      4[0m [0mye[0m [0;34m=[0m [0mmy_eulr[0m[0;34m([0m[0mf[0m[0;34m,[0m[0mx[0m[0;34m,[0m[0;36m2[0m[0;34m)[0m[0;34m[0m[0;34m[0m[0m
[0;32m----> 5[0;31m [0myi[0m [0;34m=[0m [0mmy_eulri[0m[0;34m([0m[0mf[0m[0;34m,[0m[0mx[0m[0;34m,[0m[0;36m2[0m[0;34m)[0m[0;34m[0m[0;34m[0m[0m
[0m[1;32m      6[0m [0;34m[0m[0m
[1;32m      7[0m [0mxsol[0m [0;34m=[0m [0mnp[0m[0;34m.[0m[0mlinspace[0m[0;34m([0m[0;36m0[0m[0;34m,[0m[0;36m10[0m[0;34m,[0m[0;36m1001[0m[0;34m)[0m[0;34m[0m[0;34m[0m[0m

[0;32m<ipython-input-8-32750d1e4345>[0m in [0;36mmy_eulri[0;34m(f, x, y0)[0m
[1;32m      9[0m [0;34m[0m[0m
[1;32m     10[0m         [0mF[0m [0;34m=[0m [0;32mlambda[0m [0my2[0m[0;34m:[0m [0;34m([0m[0my2[0m[0;34m-[0m[0my1[0m[0;34m-[0m[0mh[0m[0;34m*[0m[0mf[0m[0;34m([0m[0mx2[0m[0;34m,[0m [0my2[0m[0;34m)[0m[0;34m)[0m[0;34m[0m[0;34m[0m[0m
[0;32m---> 11[0;31m         [0my[0m[0;34m.[0m[0mappend[0m[0;34m([0m[0mfsolve[0m[0;34m([0m[0mF[0m[0;34m,[0m[0my1[0m[0;34m)[0m[0;34m)[0m[0;34m[0m[0;34m[0m[0m
[0m[1;32m     12[0m [0;34m[0m[0m
[1;32m     13[0m     [0;32mreturn[0m [0my[0m[0;34m[0m[0;34m[0m[0m

[0;31mNameError[0m: name 'fsolve' is not defined
NameError: name 'fsolve' is not defined

