Traceback (most recent call last):
  File "c:\users\ella metcalfe\anaconda3\envs\py37\lib\site-packages\jupyter_cache\executors\utils.py", line 56, in single_nb_execution
    record_timing=False,
  File "c:\users\ella metcalfe\anaconda3\envs\py37\lib\site-packages\nbclient\client.py", line 1204, in execute
    return NotebookClient(nb=nb, resources=resources, km=km, **kwargs).execute()
  File "c:\users\ella metcalfe\anaconda3\envs\py37\lib\site-packages\nbclient\util.py", line 84, in wrapped
    return just_run(coro(*args, **kwargs))
  File "c:\users\ella metcalfe\anaconda3\envs\py37\lib\site-packages\nbclient\util.py", line 62, in just_run
    return loop.run_until_complete(coro)
  File "c:\users\ella metcalfe\anaconda3\envs\py37\lib\asyncio\base_events.py", line 587, in run_until_complete
    return future.result()
  File "c:\users\ella metcalfe\anaconda3\envs\py37\lib\site-packages\nbclient\client.py", line 664, in async_execute
    cell, index, execution_count=self.code_cells_executed + 1
  File "c:\users\ella metcalfe\anaconda3\envs\py37\lib\site-packages\nbclient\client.py", line 965, in async_execute_cell
    await self._check_raise_for_error(cell, cell_index, exec_reply)
  File "c:\users\ella metcalfe\anaconda3\envs\py37\lib\site-packages\nbclient\client.py", line 862, in _check_raise_for_error
    raise CellExecutionError.from_cell_and_msg(cell, exec_reply_content)
nbclient.exceptions.CellExecutionError: An error occurred while executing the following cell:
------------------
import matplotlib.pyplot as plt
from mpl_toolkits.mplot3d import Axes3D  

[X,T]=np.meshgrid(x,t)

sz=16
fig, ax = plt.figure(figsize=(24,6))
plt.contourf(T, X, u, 20, cmap='RdGy')
ax.tick_params(labelsize=sz)
ax.set_xlabel('$t$', fontsize=sz,)
ax.set_ylabel('$x$', fontsize=sz,)

plt.show()
------------------

[1;31m---------------------------------------------------------------------------[0m
[1;31mTypeError[0m                                 Traceback (most recent call last)
[1;32mC:\Users\ELLAME~1\AppData\Local\Temp/ipykernel_22380/407972062.py[0m in [0;36m<module>[1;34m[0m
[0;32m      5[0m [1;33m[0m[0m
[0;32m      6[0m [0msz[0m[1;33m=[0m[1;36m16[0m[1;33m[0m[1;33m[0m[0m
[1;32m----> 7[1;33m [0mfig[0m[1;33m,[0m [0max[0m [1;33m=[0m [0mplt[0m[1;33m.[0m[0mfigure[0m[1;33m([0m[0mfigsize[0m[1;33m=[0m[1;33m([0m[1;36m24[0m[1;33m,[0m[1;36m6[0m[1;33m)[0m[1;33m)[0m[1;33m[0m[1;33m[0m[0m
[0m[0;32m      8[0m [0mplt[0m[1;33m.[0m[0mcontourf[0m[1;33m([0m[0mT[0m[1;33m,[0m [0mX[0m[1;33m,[0m [0mu[0m[1;33m,[0m [1;36m20[0m[1;33m,[0m [0mcmap[0m[1;33m=[0m[1;34m'RdGy'[0m[1;33m)[0m[1;33m[0m[1;33m[0m[0m
[0;32m      9[0m [0max[0m[1;33m.[0m[0mtick_params[0m[1;33m([0m[0mlabelsize[0m[1;33m=[0m[0msz[0m[1;33m)[0m[1;33m[0m[1;33m[0m[0m

[1;31mTypeError[0m: cannot unpack non-iterable Figure object
TypeError: cannot unpack non-iterable Figure object

