Traceback (most recent call last):
  File "c:\users\ella metcalfe\anaconda3\envs\py37\lib\site-packages\jupyter_cache\executors\utils.py", line 56, in single_nb_execution
    record_timing=False,
  File "c:\users\ella metcalfe\anaconda3\envs\py37\lib\site-packages\nbclient\client.py", line 1112, in execute
    return NotebookClient(nb=nb, resources=resources, km=km, **kwargs).execute()
  File "c:\users\ella metcalfe\anaconda3\envs\py37\lib\site-packages\nbclient\util.py", line 74, in wrapped
    return just_run(coro(*args, **kwargs))
  File "c:\users\ella metcalfe\anaconda3\envs\py37\lib\site-packages\nbclient\util.py", line 53, in just_run
    return loop.run_until_complete(coro)
  File "c:\users\ella metcalfe\anaconda3\envs\py37\lib\asyncio\base_events.py", line 587, in run_until_complete
    return future.result()
  File "c:\users\ella metcalfe\anaconda3\envs\py37\lib\site-packages\nbclient\client.py", line 554, in async_execute
    cell, index, execution_count=self.code_cells_executed + 1
  File "c:\users\ella metcalfe\anaconda3\envs\py37\lib\site-packages\nbclient\client.py", line 857, in async_execute_cell
    self._check_raise_for_error(cell, exec_reply)
  File "c:\users\ella metcalfe\anaconda3\envs\py37\lib\site-packages\nbclient\client.py", line 760, in _check_raise_for_error
    raise CellExecutionError.from_cell_and_msg(cell, exec_reply_content)
nbclient.exceptions.CellExecutionError: An error occurred while executing the following cell:
------------------
import numpy as np

n=100
x=np.linspace(0,1,n)
h = x[1]-x[0]

coeff1 = 1-h/2
coeff2 = -2-6*h**2
coeff3 = 1+h/2

A = np.diag(coeff1*np.ones((1,n-1))[0], -2) + \
    np.diag(coeff2*np.ones((1,n))[0], -1) + \
        np.diag(coeff3*np.ones((1,n+1))[0],0)

b = np.zeros((n+1,1))

A[0,[0,1,2]] = [-1,0,1]
b[0]=0
A[1, [0,1,2]] = [0,1,0]
b[1] = 1

y,_,_,_= np.linalg.lstsq(A,b,rcond = None)
y = y[1:]

fig,ax = plt.subplots(1,2)
ax[0].plot(x,y)
ax[0].set_title('Solution')
ysol = (2*np.exp(-3*x) + 3*np.exp(2*x))/5
ax[1].plot(x,abs((y.T-ysol).T))
ax[1].set_title('Error')
plt.show()
------------------

[1;31m---------------------------------------------------------------------------[0m
[1;31mNameError[0m                                 Traceback (most recent call last)
[1;32m<ipython-input-1-4ba3f68b41ed>[0m in [0;36m<module>[1;34m[0m
[0;32m     23[0m [0my[0m [1;33m=[0m [0my[0m[1;33m[[0m[1;36m1[0m[1;33m:[0m[1;33m][0m[1;33m[0m[1;33m[0m[0m
[0;32m     24[0m [1;33m[0m[0m
[1;32m---> 25[1;33m [0mfig[0m[1;33m,[0m[0max[0m [1;33m=[0m [0mplt[0m[1;33m.[0m[0msubplots[0m[1;33m([0m[1;36m1[0m[1;33m,[0m[1;36m2[0m[1;33m)[0m[1;33m[0m[1;33m[0m[0m
[0m[0;32m     26[0m [0max[0m[1;33m[[0m[1;36m0[0m[1;33m][0m[1;33m.[0m[0mplot[0m[1;33m([0m[0mx[0m[1;33m,[0m[0my[0m[1;33m)[0m[1;33m[0m[1;33m[0m[0m
[0;32m     27[0m [0max[0m[1;33m[[0m[1;36m0[0m[1;33m][0m[1;33m.[0m[0mset_title[0m[1;33m([0m[1;34m'Solution'[0m[1;33m)[0m[1;33m[0m[1;33m[0m[0m

[1;31mNameError[0m: name 'plt' is not defined
NameError: name 'plt' is not defined

