Traceback (most recent call last):
  File "c:\users\ella metcalfe\anaconda3\envs\py37\lib\site-packages\jupyter_cache\executors\utils.py", line 56, in single_nb_execution
    record_timing=False,
  File "c:\users\ella metcalfe\anaconda3\envs\py37\lib\site-packages\nbclient\client.py", line 1112, in execute
    return NotebookClient(nb=nb, resources=resources, km=km, **kwargs).execute()
  File "c:\users\ella metcalfe\anaconda3\envs\py37\lib\site-packages\nbclient\util.py", line 74, in wrapped
    return just_run(coro(*args, **kwargs))
  File "c:\users\ella metcalfe\anaconda3\envs\py37\lib\site-packages\nbclient\util.py", line 53, in just_run
    return loop.run_until_complete(coro)
  File "c:\users\ella metcalfe\anaconda3\envs\py37\lib\asyncio\base_events.py", line 587, in run_until_complete
    return future.result()
  File "c:\users\ella metcalfe\anaconda3\envs\py37\lib\site-packages\nbclient\client.py", line 554, in async_execute
    cell, index, execution_count=self.code_cells_executed + 1
  File "c:\users\ella metcalfe\anaconda3\envs\py37\lib\site-packages\nbclient\client.py", line 857, in async_execute_cell
    self._check_raise_for_error(cell, exec_reply)
  File "c:\users\ella metcalfe\anaconda3\envs\py37\lib\site-packages\nbclient\client.py", line 760, in _check_raise_for_error
    raise CellExecutionError.from_cell_and_msg(cell, exec_reply_content)
nbclient.exceptions.CellExecutionError: An error occurred while executing the following cell:
------------------
n=100
x = np.linspace(0,1,n).T
h = x[1]-x[0]

f = lambda x: sin(2*pi*x)

A = np.diag([-2]*n,0)+np.diag([1]*(n-1),1)+np.diag([1]*(n-1),-1)

A[0,[0,1]]=[1,0]
A[n-1,[n-2,n-1]]=[0,1]
F =[f(a) for a in x]
F[0]=0
F[len(F)-1] = 0

U = [h**2*a for a in np.linalg.lstsq(A,F,rcond=None)[0]]
sol = [-sin(2*pi*a)/(4*pi**2) for a in x]

fig,ax = plt.subplots(1,2)
ax[0].plot(x,U)

U = np.array(U)
sol = np.array(sol)
ax[1].plot(x,abs(U-sol))
plt.show()
------------------

[1;31m---------------------------------------------------------------------------[0m
[1;31mNameError[0m                                 Traceback (most recent call last)
[1;32m<ipython-input-1-ec000f1f5fa5>[0m in [0;36m<module>[1;34m[0m
[0;32m      1[0m [0mn[0m[1;33m=[0m[1;36m100[0m[1;33m[0m[1;33m[0m[0m
[1;32m----> 2[1;33m [0mx[0m [1;33m=[0m [0mnp[0m[1;33m.[0m[0mlinspace[0m[1;33m([0m[1;36m0[0m[1;33m,[0m[1;36m1[0m[1;33m,[0m[0mn[0m[1;33m)[0m[1;33m.[0m[0mT[0m[1;33m[0m[1;33m[0m[0m
[0m[0;32m      3[0m [0mh[0m [1;33m=[0m [0mx[0m[1;33m[[0m[1;36m1[0m[1;33m][0m[1;33m-[0m[0mx[0m[1;33m[[0m[1;36m0[0m[1;33m][0m[1;33m[0m[1;33m[0m[0m
[0;32m      4[0m [1;33m[0m[0m
[0;32m      5[0m [0mf[0m [1;33m=[0m [1;32mlambda[0m [0mx[0m[1;33m:[0m [0msin[0m[1;33m([0m[1;36m2[0m[1;33m*[0m[0mpi[0m[1;33m*[0m[0mx[0m[1;33m)[0m[1;33m[0m[1;33m[0m[0m

[1;31mNameError[0m: name 'np' is not defined
NameError: name 'np' is not defined

