Traceback (most recent call last):
  File "c:\users\ella metcalfe\anaconda3\envs\py37\lib\site-packages\jupyter_cache\executors\utils.py", line 56, in single_nb_execution
    record_timing=False,
  File "c:\users\ella metcalfe\anaconda3\envs\py37\lib\site-packages\nbclient\client.py", line 1112, in execute
    return NotebookClient(nb=nb, resources=resources, km=km, **kwargs).execute()
  File "c:\users\ella metcalfe\anaconda3\envs\py37\lib\site-packages\nbclient\util.py", line 74, in wrapped
    return just_run(coro(*args, **kwargs))
  File "c:\users\ella metcalfe\anaconda3\envs\py37\lib\site-packages\nbclient\util.py", line 53, in just_run
    return loop.run_until_complete(coro)
  File "c:\users\ella metcalfe\anaconda3\envs\py37\lib\asyncio\base_events.py", line 587, in run_until_complete
    return future.result()
  File "c:\users\ella metcalfe\anaconda3\envs\py37\lib\site-packages\nbclient\client.py", line 554, in async_execute
    cell, index, execution_count=self.code_cells_executed + 1
  File "c:\users\ella metcalfe\anaconda3\envs\py37\lib\site-packages\nbclient\client.py", line 857, in async_execute_cell
    self._check_raise_for_error(cell, exec_reply)
  File "c:\users\ella metcalfe\anaconda3\envs\py37\lib\site-packages\nbclient\client.py", line 760, in _check_raise_for_error
    raise CellExecutionError.from_cell_and_msg(cell, exec_reply_content)
nbclient.exceptions.CellExecutionError: An error occurred while executing the following cell:
------------------
M = np.diag(np.hstack((1,-2*np.ones(n-1),1)),k=0) + \
    np.diag(np.hstack((np.ones(n-1),0)),     k=-1)+ \
    np.diag(np.hstack((0,np.ones(n-1))),  k=1)

C = np.eye(n+1)-np.linalg.lstsq(np.diag(np.diag(M)),M, rcond=None)[0]
m = np.max(np.abs(np.linalg.eig(C)[0]))
sor = 1+m**2/(1+np.sqrt(1-m**2))**2
np.print(sor)
------------------

[1;31m---------------------------------------------------------------------------[0m
[1;31mAttributeError[0m                            Traceback (most recent call last)
[1;32m<ipython-input-9-74c11c384b45>[0m in [0;36m<module>[1;34m[0m
[0;32m      6[0m [0mm[0m [1;33m=[0m [0mnp[0m[1;33m.[0m[0mmax[0m[1;33m([0m[0mnp[0m[1;33m.[0m[0mabs[0m[1;33m([0m[0mnp[0m[1;33m.[0m[0mlinalg[0m[1;33m.[0m[0meig[0m[1;33m([0m[0mC[0m[1;33m)[0m[1;33m[[0m[1;36m0[0m[1;33m][0m[1;33m)[0m[1;33m)[0m[1;33m[0m[1;33m[0m[0m
[0;32m      7[0m [0msor[0m [1;33m=[0m [1;36m1[0m[1;33m+[0m[0mm[0m[1;33m**[0m[1;36m2[0m[1;33m/[0m[1;33m([0m[1;36m1[0m[1;33m+[0m[0mnp[0m[1;33m.[0m[0msqrt[0m[1;33m([0m[1;36m1[0m[1;33m-[0m[0mm[0m[1;33m**[0m[1;36m2[0m[1;33m)[0m[1;33m)[0m[1;33m**[0m[1;36m2[0m[1;33m[0m[1;33m[0m[0m
[1;32m----> 8[1;33m [0mnp[0m[1;33m.[0m[0mprint[0m[1;33m([0m[0msor[0m[1;33m)[0m[1;33m[0m[1;33m[0m[0m
[0m
[1;32m~\anaconda3\envs\py37\lib\site-packages\numpy\__init__.py[0m in [0;36m__getattr__[1;34m(attr)[0m
[0;32m    302[0m [1;33m[0m[0m
[0;32m    303[0m             raise AttributeError("module {!r} has no attribute "
[1;32m--> 304[1;33m                                  "{!r}".format(__name__, attr))
[0m[0;32m    305[0m [1;33m[0m[0m
[0;32m    306[0m         [1;32mdef[0m [0m__dir__[0m[1;33m([0m[1;33m)[0m[1;33m:[0m[1;33m[0m[1;33m[0m[0m

[1;31mAttributeError[0m: module 'numpy' has no attribute 'print'
AttributeError: module 'numpy' has no attribute 'print'

