Traceback (most recent call last):
  File "c:\users\ella metcalfe\anaconda3\envs\py37\lib\site-packages\jupyter_cache\executors\utils.py", line 56, in single_nb_execution
    record_timing=False,
  File "c:\users\ella metcalfe\anaconda3\envs\py37\lib\site-packages\nbclient\client.py", line 1112, in execute
    return NotebookClient(nb=nb, resources=resources, km=km, **kwargs).execute()
  File "c:\users\ella metcalfe\anaconda3\envs\py37\lib\site-packages\nbclient\util.py", line 74, in wrapped
    return just_run(coro(*args, **kwargs))
  File "c:\users\ella metcalfe\anaconda3\envs\py37\lib\site-packages\nbclient\util.py", line 53, in just_run
    return loop.run_until_complete(coro)
  File "c:\users\ella metcalfe\anaconda3\envs\py37\lib\asyncio\base_events.py", line 587, in run_until_complete
    return future.result()
  File "c:\users\ella metcalfe\anaconda3\envs\py37\lib\site-packages\nbclient\client.py", line 554, in async_execute
    cell, index, execution_count=self.code_cells_executed + 1
  File "c:\users\ella metcalfe\anaconda3\envs\py37\lib\site-packages\nbclient\client.py", line 857, in async_execute_cell
    self._check_raise_for_error(cell, exec_reply)
  File "c:\users\ella metcalfe\anaconda3\envs\py37\lib\site-packages\nbclient\client.py", line 760, in _check_raise_for_error
    raise CellExecutionError.from_cell_and_msg(cell, exec_reply_content)
nbclient.exceptions.CellExecutionError: An error occurred while executing the following cell:
------------------
f = lambda t,X: (998*X[0]+1998*X[1],-999*X[0]-1999*X[1])
u0 = 2
v0 = -1
X0 = [u0,v0]

i=0    
fig, ax = plt.subplots(2,2)

for _,h in enumerate([0.0025, 0.001]):
    t = np.arange(0,1,h)
    u = 2*np.exp(-t)

    Xe = my_eulr(f,t,X0)
    Xh = my_heun(f,t,X0)

    ax[0,i].plot(t,Xe[0,:]-u, 'b')
    ax[0,i].set_title('Euler, h=' + str(h))

    ax[1,i].plot(t,Xh[0,:]-u, 'r')
    ax[1,i].set_title('Heun, h=' + str(h))

    i+=1

fig.tight_layout()
plt.show()

# Using implicit Euler
h = 0.1
t = np.arange(0,1,h)
n = len(t)
u = 2*np.exp(-t)
Xi = my_euli(f,t,X0)

plt.plot(t,Xi[0,:]-u,'r')
plt.title('Implicit, h=' + str(h))
plt.show()
------------------

[1;31m---------------------------------------------------------------------------[0m
[1;31mNameError[0m                                 Traceback (most recent call last)
[1;32m<ipython-input-3-8d2cc4c93b95>[0m in [0;36m<module>[1;34m[0m
[0;32m     11[0m     [0mu[0m [1;33m=[0m [1;36m2[0m[1;33m*[0m[0mnp[0m[1;33m.[0m[0mexp[0m[1;33m([0m[1;33m-[0m[0mt[0m[1;33m)[0m[1;33m[0m[1;33m[0m[0m
[0;32m     12[0m [1;33m[0m[0m
[1;32m---> 13[1;33m     [0mXe[0m [1;33m=[0m [0mmy_eulr[0m[1;33m([0m[0mf[0m[1;33m,[0m[0mt[0m[1;33m,[0m[0mX0[0m[1;33m)[0m[1;33m[0m[1;33m[0m[0m
[0m[0;32m     14[0m     [0mXh[0m [1;33m=[0m [0mmy_heun[0m[1;33m([0m[0mf[0m[1;33m,[0m[0mt[0m[1;33m,[0m[0mX0[0m[1;33m)[0m[1;33m[0m[1;33m[0m[0m
[0;32m     15[0m [1;33m[0m[0m

[1;31mNameError[0m: name 'my_eulr' is not defined
NameError: name 'my_eulr' is not defined

